2023-10-25 16:57:22.047 WARNING (SyncWorker_3) [homeassistant.loader] We found a custom integration colorfulclouds which has not been tested by Home Assistant. This component might cause stability problems, be sure to disable it if you experience issues with Home Assistant
2023-10-25 16:57:22.047 WARNING (SyncWorker_3) [homeassistant.loader] We found a custom integration ics_calendar which has not been tested by Home Assistant. This component might cause stability problems, be sure to disable it if you experience issues with Home Assistant
2023-10-25 16:57:22.047 WARNING (SyncWorker_3) [homeassistant.loader] We found a custom integration xiaomi_miot_raw which has not been tested by Home Assistant. This component might cause stability problems, be sure to disable it if you experience issues with Home Assistant
2023-10-25 16:57:22.048 WARNING (SyncWorker_3) [homeassistant.loader] We found a custom integration hacs which has not been tested by Home Assistant. This component might cause stability problems, be sure to disable it if you experience issues with Home Assistant
2023-10-25 16:57:22.980 ERROR (MainThread) [homeassistant.setup] Error during setup of component hardware
Traceback (most recent call last):
  File "/Library/Frameworks/Python.framework/Versions/3.11/lib/python3.11/site-packages/homeassistant/setup.py", line 288, in _async_setup_component
    result = await task
             ^^^^^^^^^^
  File "/Library/Frameworks/Python.framework/Versions/3.11/lib/python3.11/site-packages/homeassistant/components/hardware/__init__.py", line 18, in async_setup
    await websocket_api.async_setup(hass)
  File "/Library/Frameworks/Python.framework/Versions/3.11/lib/python3.11/site-packages/homeassistant/components/hardware/websocket_api.py", line 37, in async_setup
    ha_psutil=await hass.async_add_executor_job(ha_psutil.PsutilWrapper),
              ^^^^^^^^^^^^^^^^^^^^^^^^^^^^^^^^^^^^^^^^^^^^^^^^^^^^^^^^^^
  File "/Library/Frameworks/Python.framework/Versions/3.11/lib/python3.11/concurrent/futures/thread.py", line 58, in run
    result = self.fn(*self.args, **self.kwargs)
             ^^^^^^^^^^^^^^^^^^^^^^^^^^^^^^^^^^
  File "/Users/liuzhou/.homeassistant/deps/lib/python/site-packages/psutil_home_assistant/__init__.py", line 15, in __init__
    psutil_spec.loader.exec_module(psutil_module)
  File "<frozen importlib._bootstrap_external>", line 940, in exec_module
  File "<frozen importlib._bootstrap>", line 241, in _call_with_frames_removed
  File "/Users/liuzhou/.homeassistant/deps/lib/python/site-packages/psutil/__init__.py", line 42, in <module>
    from . import _common
  File "/Users/liuzhou/.homeassistant/deps/lib/python/site-packages/psutil/__init__.py", line 123, in <module>
    from . import _psosx as _psplatform
  File "/Users/liuzhou/.homeassistant/deps/lib/python/site-packages/psutil/_psosx.py", line 13, in <module>
    from . import _psposix
  File "/Users/liuzhou/.homeassistant/deps/lib/python/site-packages/psutil/_psposix.py", line 28, in <module>
    from . import _psutil_osx
ImportError: cannot import name '_psutil_osx' from partially initialized module 'psutil' (most likely due to a circular import) (/Users/liuzhou/.homeassistant/deps/lib/python/site-packages/psutil/__init__.py)
2023-10-25 16:57:23.102 ERROR (MainThread) [homeassistant.setup] Setup failed for custom integration xiaomi_miot_raw: Unable to import component: No module named 'click'
Traceback (most recent call last):
  File "/Library/Frameworks/Python.framework/Versions/3.11/lib/python3.11/site-packages/homeassistant/setup.py", line 215, in _async_setup_component
    component = integration.get_component()
                ^^^^^^^^^^^^^^^^^^^^^^^^^^^
  File "/Library/Frameworks/Python.framework/Versions/3.11/lib/python3.11/site-packages/homeassistant/loader.py", line 818, in get_component
    ComponentProtocol, importlib.import_module(self.pkg_path)
                       ^^^^^^^^^^^^^^^^^^^^^^^^^^^^^^^^^^^^^^
  File "/Library/Frameworks/Python.framework/Versions/3.11/lib/python3.11/importlib/__init__.py", line 126, in import_module
    return _bootstrap._gcd_import(name[level:], package, level)
           ^^^^^^^^^^^^^^^^^^^^^^^^^^^^^^^^^^^^^^^^^^^^^^^^^^^^
  File "<frozen importlib._bootstrap>", line 1204, in _gcd_import
  File "<frozen importlib._bootstrap>", line 1176, in _find_and_load
  File "<frozen importlib._bootstrap>", line 1147, in _find_and_load_unlocked
  File "<frozen importlib._bootstrap>", line 690, in _load_unlocked
  File "<frozen importlib._bootstrap_external>", line 940, in exec_module
  File "<frozen importlib._bootstrap>", line 241, in _call_with_frames_removed
  File "/Users/liuzhou/.homeassistant/custom_components/xiaomi_miot_raw/__init__.py", line 24, in <module>
    from miio.exceptions import DeviceException
  File "/Users/liuzhou/.homeassistant/deps/lib/python/site-packages/miio/__init__.py", line 12, in <module>
    from miio.device import Device, DeviceStatus  # isort: skip
    ^^^^^^^^^^^^^^^^^^^^^^^^^^^^^^^^^^^^^^^^^^^^
  File "/Users/liuzhou/.homeassistant/deps/lib/python/site-packages/miio/device.py", line 8, in <module>
    import click
ModuleNotFoundError: No module named 'click'
2023-10-25 16:57:23.268 ERROR (SyncWorker_0) [custom_components.ics_calendar] No configuration found! If you upgraded from ics_calendar v3.2.0 or older, you need to update your configuration! See https://github.com/franc6/ics_calendar/blob/releases/UpgradeTo4.0AndLater.md for more information.
2023-10-25 16:57:23.331 ERROR (MainThread) [homeassistant.setup] Unable to set up dependencies of default_config. Setup failed for dependencies: hardware
2023-10-25 16:57:23.331 ERROR (MainThread) [homeassistant.setup] Setup failed for default_config: (DependencyError(...), 'Could not setup dependencies: hardware')
2023-10-25 16:57:23.331 WARNING (MainThread) [homeassistant.components.weather] custom_components.colorfulclouds.weather::None is using a forecast attribute on an instance of WeatherEntity, this is deprecated and will be unsupported from Home Assistant 2024.3. Please report it to the custom integration author.
2023-10-25 16:57:23.333 ERROR (MainThread) [homeassistant.components.calendar] Error while setting up ics_calendar platform for calendar
Traceback (most recent call last):
  File "/Library/Frameworks/Python.framework/Versions/3.11/lib/python3.11/site-packages/homeassistant/helpers/entity_platform.py", line 359, in _async_setup_platform
    await asyncio.shield(task)
  File "/Library/Frameworks/Python.framework/Versions/3.11/lib/python3.11/concurrent/futures/thread.py", line 58, in run
    result = self.fn(*self.args, **self.kwargs)
             ^^^^^^^^^^^^^^^^^^^^^^^^^^^^^^^^^^
  File "/Users/liuzhou/.homeassistant/custom_components/ics_calendar/calendar.py", line 95, in setup_platform
    calendar_devices.append(ICSCalendarEntity(entity_id, device_data))
                            ^^^^^^^^^^^^^^^^^^^^^^^^^^^^^^^^^^^^^^^^^
  File "/Users/liuzhou/.homeassistant/custom_components/ics_calendar/calendar.py", line 116, in __init__
    self.data = ICSCalendarData(device_data)
                ^^^^^^^^^^^^^^^^^^^^^^^^^^^^
  File "/Users/liuzhou/.homeassistant/custom_components/ics_calendar/calendar.py", line 196, in __init__
    self.parser = ICalendarParser.get_instance(device_data[CONF_PARSER])
                  ^^^^^^^^^^^^^^^^^^^^^^^^^^^^^^^^^^^^^^^^^^^^^^^^^^^^^^
  File "/Users/liuzhou/.homeassistant/custom_components/ics_calendar/icalendarparser.py", line 33, in get_instance
    parser_cls = ICalendarParser.get_class(parser)
                 ^^^^^^^^^^^^^^^^^^^^^^^^^^^^^^^^^
  File "/Users/liuzhou/.homeassistant/custom_components/ics_calendar/icalendarparser.py", line 22, in get_class
    parser_module_name = ".parsers.parser_" + parser
                         ~~~~~~~~~~~~~~~~~~~^~~~~~~~
TypeError: can only concatenate str (not "NoneType") to str
2023-10-25 16:57:24.259 WARNING (SyncWorker_0) [scapy.runtime] No IPv4 address found on anpi2 !
2023-10-25 16:57:24.285 WARNING (SyncWorker_0) [scapy.runtime] No IPv4 address found on anpi1 !
2023-10-25 16:57:24.302 WARNING (SyncWorker_0) [scapy.runtime] more No IPv4 address found on anpi0 !
2023-10-25 16:58:19.452 ERROR (MainThread) [root] Uncaught exception
Traceback (most recent call last):
  File "/Library/Frameworks/Python.framework/Versions/3.11/bin/hass", line 8, in <module>
    sys.exit(main())
             ^^^^^^
  File "/Library/Frameworks/Python.framework/Versions/3.11/lib/python3.11/site-packages/homeassistant/__main__.py", line 207, in main
    if os.path.getsize(fault_file_name) == 0:
       ^^^^^^^^^^^^^^^^^^^^^^^^^^^^^^^^
  File "<frozen genericpath>", line 50, in getsize
FileNotFoundError: [Errno 2] No such file or directory: '/Users/liuzhou/.homeassistant/home-assistant.log.fault'
