2023-10-25 16:06:05.985 WARNING (SyncWorker_0) [homeassistant.loader] We found a custom integration colorfulclouds which has not been tested by Home Assistant. This component might cause stability problems, be sure to disable it if you experience issues with Home Assistant
2023-10-25 16:06:05.985 WARNING (SyncWorker_0) [homeassistant.loader] We found a custom integration ics_calendar which has not been tested by Home Assistant. This component might cause stability problems, be sure to disable it if you experience issues with Home Assistant
2023-10-25 16:06:05.985 WARNING (SyncWorker_0) [homeassistant.loader] We found a custom integration xiaomi_miot_raw which has not been tested by Home Assistant. This component might cause stability problems, be sure to disable it if you experience issues with Home Assistant
2023-10-25 16:06:05.986 WARNING (SyncWorker_0) [homeassistant.loader] We found a custom integration hacs which has not been tested by Home Assistant. This component might cause stability problems, be sure to disable it if you experience issues with Home Assistant
2023-10-25 16:06:06.861 ERROR (MainThread) [homeassistant.setup] Error during setup of component hardware
Traceback (most recent call last):
  File "/Library/Frameworks/Python.framework/Versions/3.11/lib/python3.11/site-packages/homeassistant/setup.py", line 288, in _async_setup_component
    result = await task
             ^^^^^^^^^^
  File "/Library/Frameworks/Python.framework/Versions/3.11/lib/python3.11/site-packages/homeassistant/components/hardware/__init__.py", line 18, in async_setup
    await websocket_api.async_setup(hass)
  File "/Library/Frameworks/Python.framework/Versions/3.11/lib/python3.11/site-packages/homeassistant/components/hardware/websocket_api.py", line 37, in async_setup
    ha_psutil=await hass.async_add_executor_job(ha_psutil.PsutilWrapper),
              ^^^^^^^^^^^^^^^^^^^^^^^^^^^^^^^^^^^^^^^^^^^^^^^^^^^^^^^^^^
  File "/Library/Frameworks/Python.framework/Versions/3.11/lib/python3.11/concurrent/futures/thread.py", line 58, in run
    result = self.fn(*self.args, **self.kwargs)
             ^^^^^^^^^^^^^^^^^^^^^^^^^^^^^^^^^^
  File "/Users/liuzhou/.homeassistant/deps/lib/python/site-packages/psutil_home_assistant/__init__.py", line 15, in __init__
    psutil_spec.loader.exec_module(psutil_module)
  File "<frozen importlib._bootstrap_external>", line 940, in exec_module
  File "<frozen importlib._bootstrap>", line 241, in _call_with_frames_removed
  File "/Users/liuzhou/.homeassistant/deps/lib/python/site-packages/psutil/__init__.py", line 42, in <module>
    from . import _common
  File "/Users/liuzhou/.homeassistant/deps/lib/python/site-packages/psutil/__init__.py", line 123, in <module>
    from . import _psosx as _psplatform
  File "/Users/liuzhou/.homeassistant/deps/lib/python/site-packages/psutil/_psosx.py", line 13, in <module>
    from . import _psposix
  File "/Users/liuzhou/.homeassistant/deps/lib/python/site-packages/psutil/_psposix.py", line 28, in <module>
    from . import _psutil_osx
ImportError: cannot import name '_psutil_osx' from partially initialized module 'psutil' (most likely due to a circular import) (/Users/liuzhou/.homeassistant/deps/lib/python/site-packages/psutil/__init__.py)
2023-10-25 16:06:07.027 ERROR (MainThread) [homeassistant.setup] Setup failed for custom integration xiaomi_miot_raw: Unable to import component: No module named 'click'
Traceback (most recent call last):
  File "/Library/Frameworks/Python.framework/Versions/3.11/lib/python3.11/site-packages/homeassistant/setup.py", line 215, in _async_setup_component
    component = integration.get_component()
                ^^^^^^^^^^^^^^^^^^^^^^^^^^^
  File "/Library/Frameworks/Python.framework/Versions/3.11/lib/python3.11/site-packages/homeassistant/loader.py", line 818, in get_component
    ComponentProtocol, importlib.import_module(self.pkg_path)
                       ^^^^^^^^^^^^^^^^^^^^^^^^^^^^^^^^^^^^^^
  File "/Library/Frameworks/Python.framework/Versions/3.11/lib/python3.11/importlib/__init__.py", line 126, in import_module
    return _bootstrap._gcd_import(name[level:], package, level)
           ^^^^^^^^^^^^^^^^^^^^^^^^^^^^^^^^^^^^^^^^^^^^^^^^^^^^
  File "<frozen importlib._bootstrap>", line 1204, in _gcd_import
  File "<frozen importlib._bootstrap>", line 1176, in _find_and_load
  File "<frozen importlib._bootstrap>", line 1147, in _find_and_load_unlocked
  File "<frozen importlib._bootstrap>", line 690, in _load_unlocked
  File "<frozen importlib._bootstrap_external>", line 940, in exec_module
  File "<frozen importlib._bootstrap>", line 241, in _call_with_frames_removed
  File "/Users/liuzhou/.homeassistant/custom_components/xiaomi_miot_raw/__init__.py", line 24, in <module>
    from miio.exceptions import DeviceException
  File "/Users/liuzhou/.homeassistant/deps/lib/python/site-packages/miio/__init__.py", line 12, in <module>
    from miio.device import Device, DeviceStatus  # isort: skip
    ^^^^^^^^^^^^^^^^^^^^^^^^^^^^^^^^^^^^^^^^^^^^
  File "/Users/liuzhou/.homeassistant/deps/lib/python/site-packages/miio/device.py", line 8, in <module>
    import click
ModuleNotFoundError: No module named 'click'
2023-10-25 16:06:07.140 ERROR (MainThread) [homeassistant.config] Platform error: calendar
Traceback (most recent call last):
  File "/Library/Frameworks/Python.framework/Versions/3.11/lib/python3.11/site-packages/homeassistant/config.py", line 919, in async_process_component_config
    platform = p_integration.get_platform(domain)
               ^^^^^^^^^^^^^^^^^^^^^^^^^^^^^^^^^^
  File "/Library/Frameworks/Python.framework/Versions/3.11/lib/python3.11/site-packages/homeassistant/loader.py", line 838, in get_platform
    cache[full_name] = self._import_platform(platform_name)
                       ^^^^^^^^^^^^^^^^^^^^^^^^^^^^^^^^^^^^
  File "/Library/Frameworks/Python.framework/Versions/3.11/lib/python3.11/site-packages/homeassistant/loader.py", line 855, in _import_platform
    return importlib.import_module(f"{self.pkg_path}.{platform_name}")
           ^^^^^^^^^^^^^^^^^^^^^^^^^^^^^^^^^^^^^^^^^^^^^^^^^^^^^^^^^^^
  File "/Library/Frameworks/Python.framework/Versions/3.11/lib/python3.11/importlib/__init__.py", line 126, in import_module
    return _bootstrap._gcd_import(name[level:], package, level)
           ^^^^^^^^^^^^^^^^^^^^^^^^^^^^^^^^^^^^^^^^^^^^^^^^^^^^
  File "<frozen importlib._bootstrap>", line 1204, in _gcd_import
  File "<frozen importlib._bootstrap>", line 1176, in _find_and_load
  File "<frozen importlib._bootstrap>", line 1147, in _find_and_load_unlocked
  File "<frozen importlib._bootstrap>", line 690, in _load_unlocked
  File "<frozen importlib._bootstrap_external>", line 940, in exec_module
  File "<frozen importlib._bootstrap>", line 241, in _call_with_frames_removed
  File "/Library/Frameworks/Python.framework/Versions/3.11/lib/python3.11/site-packages/homeassistant/components/caldav/calendar.py", line 9, in <module>
    import caldav
  File "/Users/liuzhou/.homeassistant/deps/lib/python/site-packages/caldav/__init__.py", line 8, in <module>
    from .davclient import DAVClient
  File "/Users/liuzhou/.homeassistant/deps/lib/python/site-packages/caldav/davclient.py", line 8, in <module>
    from caldav.elements import cdav
  File "/Users/liuzhou/.homeassistant/deps/lib/python/site-packages/caldav/elements/cdav.py", line 17, in <module>
    from .base import BaseElement, NamedBaseElement, ValuedBaseElement
  File "/Users/liuzhou/.homeassistant/deps/lib/python/site-packages/caldav/elements/base.py", line 5, in <module>
    from lxml import etree
ImportError: cannot import name 'etree' from 'lxml' (/Users/liuzhou/.homeassistant/deps/lib/python/site-packages/lxml/__init__.py)
2023-10-25 16:06:07.271 ERROR (MainThread) [homeassistant.setup] Unable to set up dependencies of default_config. Setup failed for dependencies: hardware
2023-10-25 16:06:07.271 ERROR (MainThread) [homeassistant.setup] Setup failed for default_config: (DependencyError(...), 'Could not setup dependencies: hardware')
2023-10-25 16:06:07.272 WARNING (MainThread) [homeassistant.components.weather] custom_components.colorfulclouds.weather::None is using a forecast attribute on an instance of WeatherEntity, this is deprecated and will be unsupported from Home Assistant 2024.3. Please report it to the custom integration author.
2023-10-25 16:06:08.925 WARNING (SyncWorker_3) [scapy.runtime] No IPv4 address found on anpi2 !
2023-10-25 16:06:08.945 WARNING (SyncWorker_3) [scapy.runtime] No IPv4 address found on anpi1 !
2023-10-25 16:06:08.957 WARNING (SyncWorker_3) [scapy.runtime] more No IPv4 address found on anpi0 !
2023-10-25 16:07:49.576 WARNING (MainThread) [custom_components.hacs] A timeout of 60! seconds was encountered while downloading https://github.com/hacs/integration/releases/download/1.33.0/hacs.zip, using over 60 seconds to download a single file is not normal. This is not a problem with HACS but how your host communicates with GitHub. Retrying up to 5 times to mask/hide your host/network problems to stop the flow of issues opened about it. Tries left 4
2023-10-25 16:08:51.577 WARNING (MainThread) [custom_components.hacs] A timeout of 60! seconds was encountered while downloading https://github.com/hacs/integration/releases/download/1.33.0/hacs.zip, using over 60 seconds to download a single file is not normal. This is not a problem with HACS but how your host communicates with GitHub. Retrying up to 5 times to mask/hide your host/network problems to stop the flow of issues opened about it. Tries left 3
2023-10-25 16:09:53.577 WARNING (MainThread) [custom_components.hacs] A timeout of 60! seconds was encountered while downloading https://github.com/hacs/integration/releases/download/1.33.0/hacs.zip, using over 60 seconds to download a single file is not normal. This is not a problem with HACS but how your host communicates with GitHub. Retrying up to 5 times to mask/hide your host/network problems to stop the flow of issues opened about it. Tries left 2
2023-10-25 16:10:55.577 WARNING (MainThread) [custom_components.hacs] A timeout of 60! seconds was encountered while downloading https://github.com/hacs/integration/releases/download/1.33.0/hacs.zip, using over 60 seconds to download a single file is not normal. This is not a problem with HACS but how your host communicates with GitHub. Retrying up to 5 times to mask/hide your host/network problems to stop the flow of issues opened about it. Tries left 1
2023-10-25 16:11:57.581 WARNING (MainThread) [custom_components.hacs] A timeout of 60! seconds was encountered while downloading https://github.com/hacs/integration/releases/download/1.33.0/hacs.zip, using over 60 seconds to download a single file is not normal. This is not a problem with HACS but how your host communicates with GitHub. Retrying up to 5 times to mask/hide your host/network problems to stop the flow of issues opened about it. Tries left 0
2023-10-25 16:11:58.584 ERROR (MainThread) [custom_components.hacs] <Integration hacs/integration> [hacs.zip] was not downloaded
2023-10-25 16:11:58.770 ERROR (MainThread) [homeassistant.components.websocket_api.http.connection] [5132526656] Error handling message: Unknown error (unknown_error) liuzhou from 127.0.0.1 (Mozilla/5.0 (Macintosh; Intel Mac OS X 10_15_7) AppleWebKit/537.36 (KHTML, like Gecko) Chrome/118.0.0.0 Safari/537.36)
Traceback (most recent call last):
  File "/Library/Frameworks/Python.framework/Versions/3.11/lib/python3.11/site-packages/homeassistant/components/websocket_api/decorators.py", line 26, in _handle_async_response
    await func(hass, connection, msg)
  File "/Users/liuzhou/.homeassistant/custom_components/hacs/websocket/repository.py", line 216, in hacs_repository_download
    await repository.async_install()
  File "/Users/liuzhou/.homeassistant/custom_components/hacs/repositories/base.py", line 899, in async_install
    await self.async_install_repository()
  File "/Users/liuzhou/.homeassistant/custom_components/hacs/repositories/base.py", line 995, in async_install_repository
    raise HacsException("Could not download, see log for details")
custom_components.hacs.exceptions.HacsException: Could not download, see log for details
